Workbook
Name _10000: [1]Регион!#REF!
Name _1080: [2]Регион!#REF!
Name _1090: [2]Регион!#REF!
Name _1100: [2]Регион!#REF!
Name _1110: [2]Регион!#REF!
Name _2: [1]Регион!#REF!
Name _2010: #REF!
Name _2080: [2]Регион!#REF!
Name _2090: [2]Регион!#REF!
Name _2100: [2]Регион!#REF!
Name _2110: [2]Регион!#REF!
Name _3080: [2]Регион!#REF!
Name _3090: [2]Регион!#REF!
Name _3100: [2]Регион!#REF!
Name _3110: [2]Регион!#REF!
Name _4080: [2]Регион!#REF!
Name _4090: [2]Регион!#REF!
Name _4100: [2]Регион!#REF!
Name _4110: [2]Регион!#REF!
Name _5080: [2]Регион!#REF!
Name _5090: [2]Регион!#REF!
Name _5100: [2]Регион!#REF!
Name _5110: [2]Регион!#REF!
Name _6080: [2]Регион!#REF!
Name _6090: [2]Регион!#REF!
Name _6100: [2]Регион!#REF!
Name _6110: [2]Регион!#REF!
Name _7031_1: [2]Регион!#REF!
Name _7031_2: [2]Регион!#REF!
Name _7032_1: [2]Регион!#REF!
Name _7032_2: [2]Регион!#REF!
Name _7033_1: [2]Регион!#REF!
Name _7033_2: [2]Регион!#REF!
Name _7034_1: [2]Регион!#REF!
Name _7034_2: [2]Регион!#REF!
Name A2298668K: [3]AustralianNA2!$DF$1:$DF$10,[3]AustralianNA2!$DF$12:$DF$244
Name A2302665R_Latest: [3]AustralianNA!$CB$243
Name A2302667V: [3]AustralianNA!$CD$1:$CD$10,[3]AustralianNA!$CD$11:$CD$243
Name A2303329W_Latest: [3]AustralianNA!$S$244
Name A2303331J: [3]AustralianNA!$T$1:$T$10,[3]AustralianNA!$T$12:$T$244
Name A2303331J_Data: [3]AustralianNA!$T$12:$T$244
Name A2303331J_Latest: [3]AustralianNA!$T$244
Name A2303335T: [3]AustralianNA!$V$1:$V$10,[3]AustralianNA!$V$12:$V$244
Name A2303335T_Data: [3]AustralianNA!$V$12:$V$244
Name A2303335T_Latest: [3]AustralianNA!$V$244
Name A2303337W: [3]AustralianNA!$W$1:$W$10,[3]AustralianNA!$W$12:$W$244
Name A2303337W_Data: [3]AustralianNA!$W$12:$W$244
Name A2303339A: [3]AustralianNA!$X$1:$X$10,[3]AustralianNA!$X$12:$X$244
Name A2303339A_Data: [3]AustralianNA!$X$12:$X$244
Name A2303339A_Latest: [3]AustralianNA!$X$244
Name A2303341L: [3]AustralianNA!$Y$1:$Y$10,[3]AustralianNA!$Y$12:$Y$244
Name A2303341L_Latest: [3]AustralianNA!$Y$244
Name A2303345W: [3]AustralianNA!$AA$1:$AA$10,[3]AustralianNA!$AA$12:$AA$244
Name A2303345W_Data: [3]AustralianNA!$AA$12:$AA$244
Name A2303347A: [3]AustralianNA!$AB$1:$AB$10,[3]AustralianNA!$AB$12:$AB$244
Name A2303347A_Data: [3]AustralianNA!$AB$12:$AB$244
Name A2303347A_Latest: [3]AustralianNA!$AB$244
Name A2303349F_Data: [3]AustralianNA!$AC$12:$AC$244
Name A2303349F_Latest: [3]AustralianNA!$AC$244
Name A2303351T: [3]AustralianNA!$AD$1:$AD$10,[3]AustralianNA!$AD$12:$AD$244

Sheet F2

Sheet DataF3
A1: year | B1: High income | C1: Middle and low income
A2: 2001 | B2: 0.7738202 | C2: =1-B2 -> 0.2261798
A3: 2002 | B3: 0.7694009 | C3: =1-B3 -> 0.2305991
A4: 2003 | B4: 0.7719812 | C4: =1-B4 -> 0.2280188
A5: 2004 | B5: 0.775029 | C5: =1-B5 -> 0.224971
A6: 2005 | B6: 0.7631019 | C6: =1-B6 -> 0.2368981
A7: 2006 | B7: 0.7487888 | C7: =1-B7 -> 0.2512112
A8: 2007 | B8: 0.7574551 | C8: =1-B8 -> 0.2425449
A9: 2008 | B9: 0.7638805 | C9: =1-B9 -> 0.2361195
A10: 2009 | B10: 0.759133 | C10: =1-B10 -> 0.240867
A11: 2010 | B11: 0.747589 | C11: =1-B11 -> 0.252411
A12: 2011 | B12: 0.7583146 | C12: =1-B12 -> 0.2416854
A13: 2012 | B13: 0.7677397 | C13: =1-B13 -> 0.2322603
... A23: 2022 | B23: 0.7018187 | C23: =1-B23 -> 0.2981813

Sheet DataF4
C1: GDP 2022 | D1: Offshore wealth bn | E1: Offshore wealth /GDP
A2: Iran | B2: Iran (Islamic Republic of) | C2: 352.21301 | D2: 2.4288454 | E2: 0.0068959561
A3: India | B3: India | C3: 3386.4029 | D3: 26.021391 | E3: 0.0076840799
A4: Indonesia | B4: Indonesia | C4: 1318.807 | D4: 28.966833 | E4: 0.021964421
A5: Brazil | B5: Brazil | C5: 1924.1339 | D5: 77.173401 | E5: 0.040108122
A6: USA | B6: United States of America | C6: 25464.475 | D6: 1499.2886 | E6: 0.058877654
A7: Korea | B7: Korea (the Republic of) | C7: 1665.2455 | D7: 102.27711 | E7: 0.061418634
A8: Nigeria | B8: Nigeria | C8: =477375987712/1000000000 -> 477.37599 | D8: 31.087618 | E8: 0.06512187
A9: Japan | B9: Japan | C9: 4233.538 | D9: 317.54413 | E9: 0.075006798
A10: Argentina | B10: Argentina | C10: 632.77027 | D10: 47.721878 | E10: 0.075417385
A11: Norway | B11: Norway | C11: 579.267 | D11: 45.811775 | E11: 0.079085767
A12: Germany | B12: Germany | C12: 4075.395 | D12: 353.02353 | E12: 0.086623147
A13: Colombia | B13: Colombia | C13: 343.93899 | D13: 31.195257 | E13: 0.090699971
A14: Finland | B14: Finland | C14: 281.04701 | D14: 25.806553 | E14: 0.091822907
A15: Italy | B15: Italy | C15: 2012.013 | D15: 187.30733 | E15: 0.09309449
A16: Sweden | B16: Sweden | C16: 585.93903 | D16: 56.709248 | E16: 0.096783534
A17: Spain | B17: Spain | C17: 1400.52 | D17: 139.83559 | E17: 0.099845476
A18: China | B18: China | C18: 18100.045 | D18: 1949.3284 | E18: 0.10769743
A19: Australia | B19: Australia | C19: 1701.893 | D19: 190.87227 | E19: 0.11215292
A20: Russia | B20: Russian Federation | C20: 2240.4223 | D20: 253.9256 | E20: 0.11333827
... A39: UAE | B39: United Arab Emirates | C39: 507.53493 | D39: 545.35034 | E39: 1.074508

Sheet DataF5
B1: Offshore wealth, % of world GDP
B2: Offshore wealth | C2: Untaxed offshore wealth: high-end | D2: Untaxed offshore wealth: main | E2: Untaxed offshore wealth: low end | F2: Fraction taxed (high evasion scenario) | G2: Fraction taxed (central scenario) | H2: Fraction taxed (low evasion scenario) | J2: World GDP | K2: Offshore wealth
A3: 2000
A4: 2001 | B4: =K4/J4 -> 0.094147315 | C4: =(1-F4)*$B4 -> 0.089439949 | D4: =(1-G4)*$B4 -> 0.089439949 | E4: =(1-H4)*$B4 -> 0.089439949 | F4: =G4-(H4-G4) -> 0.05 | G4: 0.05 | H4: =G4 -> 0.05 | J4: 34810 | K4: 3277.268
A5: 2002 | B5: =K5/J5 -> 0.093125253 | C5: =(1-F5)*$B5 -> 0.08846899 | D5: =(1-G5)*$B5 -> 0.08846899 | E5: =(1-H5)*$B5 -> 0.08846899 | F5: =G5-(H5-G5) -> 0.05 | G5: 0.05 | H5: =G5 -> 0.05 | J5: 35600 | K5: 3315.259
A6: 2003 | B6: =K6/J6 -> 0.088196412 | C6: =(1-F6)*$B6 -> 0.083786591 | D6: =(1-G6)*$B6 -> 0.083786591 | E6: =(1-H6)*$B6 -> 0.083786591 | F6: =G6-(H6-G6) -> 0.05 | G6: 0.05 | H6: =G6 -> 0.05 | J6: 39890 | K6: 3518.1549
A7: 2004 | B7: =K7/J7 -> 0.094836885 | C7: =(1-F7)*$B7 -> 0.09009504 | D7: =(1-G7)*$B7 -> 0.09009504 | E7: =(1-H7)*$B7 -> 0.09009504 | F7: =G7-(H7-G7) -> 0.05 | G7: 0.05 | H7: =G7 -> 0.05 | J7: 44810 | K7: 4249.6408
A8: 2005 | B8: =K8/J8 -> 0.093891775 | C8: =(1-F8)*$B8 -> 0.089197186 | D8: =(1-G8)*$B8 -> 0.089197186 | E8: =(1-H8)*$B8 -> 0.089197186 | F8: =G8-(H8-G8) -> 0.05 | G8: 0.05 | H8: =G8 -> 0.05 | J8: 48520 | K8: 4555.6289
A9: 2006 | B9: =K9/J9 -> 0.097116227 | C9: =(1-F9)*$B9 -> 0.092260416 | D9: =(1-G9)*$B9 -> 0.092260416 | E9: =(1-H9)*$B9 -> 0.092260416 | F9: =G9-(H9-G9) -> 0.05 | G9: 0.05 | H9: =G9 -> 0.05 | J9: 51690 | K9: 5019.9378
A10: 2007 | B10: =K10/J10 -> 0.11545814 | C10: =(1-F10)*$B10 -> 0.10968523 | D10: =(1-G10)*$B10 -> 0.10968523 | E10: =(1-H10)*$B10 -> 0.10968523 | F10: =G10-(H10-G10) -> 0.05 | G10: 0.05 | H10: =G10 -> 0.05 | J10: 58340 | K10: 6735.8279
A11: 2008 | B11: =K11/J11 -> 0.087654372 | C11: =(1-F11)*$B11 -> 0.078888935 | D11: =(1-G11)*$B11 -> 0.078888935 | E11: =(1-H11)*$B11 -> 0.078888935 | F11: =G11-(H11-G11) -> 0.1 | G11: 0.1 | H11: =G11 -> 0.1 | J11: 64000 | K11: 5609.8798
A12: 2009 | B12: =K12/J12 -> 0.10331268 | C12: =(1-F12)*$B12 -> 0.092981409 | D12: =(1-G12)*$B12 -> 0.092981409 | E12: =(1-H12)*$B12 -> 0.092981409 | F12: =G12-(H12-G12) -> 0.1 | G12: 0.1 | H12: =G12 -> 0.1 | J12: 60690 | K12: 6270.0463
A13: 2010 | B13: =K13/J13 -> 0.087030188 | C13: =(1-F13)*$B13 -> 0.07832717 | D13: =(1-G13)*$B13 -> 0.07832717 | E13: =(1-H13)*$B13 -> 0.07832717 | F13: =G13-(H13-G13) -> 0.1 | G13: 0.1 | H13: =G13 -> 0.1 | J13: 66400 | K13: 5778.8045
A14: 2011 | B14: =K14/J14 -> 0.087952976 | C14: =(1-F14)*$B14 -> 0.079157678 | D14: =(1-G14)*$B14 -> 0.079157678 | E14: =(1-H14)*$B14 -> 0.079157678 | F14: =G14-(H14-G14) -> 0.1 | G14: 0.1 | H14: =G14 -> 0.1 | J14: 73900 | K14: 6499.7249
A15: 2012 | B15: =K15/J15 -> 0.10895288 | C15: =(1-F15)*$B15 -> 0.092609951 | D15: =(1-G15)*$B15 -> 0.092609951 | E15: =(1-H15)*$B15 -> 0.092609951 | F15: =G15-(H15-G15) -> 0.15 | G15: 0.15 | H15: =G15 -> 0.15 | J15: 75230 | K15: 8196.5254
... A18: 2015 | B18: =K18/J18 -> 0.12379781 | C18: =(1-F18)*$B18 -> 0.099038251 | D18: =(1-G18)*$B18 -> 0.099038251 | E18: =(1-H18)*$B18 -> 0.099038251 | F18: =G18-(H18-G18) -> 0.2 | G18: 0.2 | H18: =G18 -> 0.2 | J18: 75120 | K18: 9299.6918
A19: 2016 | B19: =K19/J19 -> 0.10117812 | C19: =(1-F19)*$B19 -> 0.080942494 | D19: =(1-G19)*$B19 -> 0.075883588 | E19: =(1-H19)*$B19 -> 0.070824682 | F19: =G19-(H19-G19) -> 0.2 | G19: 0.25 | H19: 0.3 | J19: 76440 | K19: 7734.0553
A20: 2017 | B20: =K20/J20 -> 0.11351652 | C20: =(1-F20)*$B20 -> 0.068109913 | D20: =(1-G20)*$B20 -> 0.056758261 | E20: =(1-H20)*$B20 -> 0.045406609 | F20: =G20-(H20-G20) -> 0.4 | G20: 0.5 | H20: 0.6 | J20: 81200 | K20: 9217.5416
A21: 2018 | B21: =K21/J21 -> 0.10018927 | C21: =(1-F21)*$B21 -> 0.050094633 | D21: =(1-G21)*$B21 -> 0.040075707 | E21: =(1-H21)*$B21 -> 0.03005678 | F21: =G21-(H21-G21) -> 0.5 | G21: 0.6 | H21: 0.7 | J21: 86030 | K21: 8619.2826
A22: 2019 | B22: =K22/J22 -> 0.12025419 | C22: =(1-F22)*$B22 -> 0.057120739 | D22: =(1-G22)*$B22 -> 0.042088966 | E22: =(1-H22)*$B22 -> 0.027057192 | F22: =G22-(H22-G22) -> 0.525 | G22: 0.65 | H22: 0.775 | J22: 87330 | K22: 10501.798
A23: 2020 | B23: =K23/J23 -> 0.1474475 | C23: =(1-F23)*$B23 -> 0.054555575 | D23: =(1-G23)*$B23 -> 0.039810825 | E23: =(1-H23)*$B23 -> 0.022117125 | F23: =0.9*70% -> 0.63 | G23: =70%+0.1*0.3 -> 0.73 | H23: =70%+0.5*0.3 -> 0.85 | J23: 85050 | K23: 12540.41
A24: 2021 | B24: =K24/J24 -> 0.14187061 | C24: =(1-F24)*$B24 -> 0.052492125 | D24: =(1-G24)*$B24 -> 0.038305064 | E24: =(1-H24)*$B24 -> 0.021280591 | F24: =0.9*70%+0*0.3 -> 0.63 | G24: =70%+0.1*0.3 -> 0.73 | H24: =70%+0.5*0.3 -> 0.85 | J24: 96590 | K24: 13703.282
A25: 2022 | B25: =K25/J25 -> 0.11941856 | C25: =(1-F25)*$B25 -> 0.044184866 | D25: =(1-G25)*$B25 -> 0.03224301 | E25: =(1-H25)*$B25 -> 0.017912784 | F25: =0.9*70%+0*0.3 -> 0.63 | G25: =70%+0.1*0.3 -> 0.73 | H25: =70%+0.5*0.3 -> 0.85 | J25: 101100 | K25: 12073.216

Sheet AppendixTables

Sheet T.A1
B3: Table A1: The world's offshore household financial wealth
C4: Billions current US$ | J4: % of world GDP
B5: World GDP | C5: Offshore wealth | D5: Of which: portfolio securities | E5: Of which: bank deposits | F5: Of which: Switzerland | G5: % declared | H5: Offshore wealth, BCG | I5: Offshore wealth, TJN | J5: Offshore wealth | K5: Of which: portfolio securities | L5: Of which: bank deposits | M5: Of which: Switzerland | N5: Offshore wealth, BCG | O5: Offshore wealth, TJN | Q5: Switzerland securities | R5: Switzerland deposits | S5: Switzerland total | U5: BIS deposits in bank havens | W5: Deposits/total | X5: Switzerland/total
A6: 1999 | F6: 1231.6908 | Q6: 928.14763 | R6: 303.54321 | T6: =R6/Q6 -> 0.32704195
A7: 2000 | B7: 33276.21 | F7: 1197.4418 | G7: 0.05 | M7: =F7/$B7 -> 0.03598492 | Q7: 878.46998 | R7: 318.97179 | T7: =R7/Q7 -> 0.36309925 | U7: 1105.5885
A8: 2001 | B8: 34810 | C8: =D8+E8 -> 3311.5496 | D8: 2792.1756 | E8: =E9*U8/U9 -> 519.37393 | F8: 1271.2507 | G8: 0.05 | J8: =C8/$B8 -> 0.095132134 | K8: =D8/$B8 -> 0.080211883 | L8: =E8/$B8 -> 0.014920251 | M8: =F8/$B8 -> 0.036519698 | Q8: 940.97611 | R8: 330.27458 | T8: =R8/Q8 -> 0.35099146 | U8: 1197.1868 | W8: =E8/C8 -> 0.15683713 | X8: =F8/C8 -> 0.38388394
A9: 2002 | B9: 35600 | C9: =D9+E9 -> 3326.7462 | D9: 2743.2189 | E9: =E10*U9/U10 -> 583.52732 | F9: 1282.4401 | G9: 0.05 | J9: =C9/$B9 -> 0.093447928 | K9: =D9/$B9 -> 0.077056711 | L9: =E9/$B9 -> 0.016391217 | M9: =F9/$B9 -> 0.0360236 | P9: =AVERAGE(C8:C9)/B9 -> 0.093234491 | Q9: 964.52758 | R9: 317.91256 | T9: =R9/Q9 -> 0.32960443 | U9: 1345.064 | W9: =E9/C9 -> 0.17540482 | X9: =F9/C9 -> 0.38549383
A10: 2003 | B10: 39890 | C10: =D10+E10 -> 3569.3503 | D10: 2899.6006 | E10: =E11*U10/U11 -> 669.74968 | F10: 1556.1789 | G10: 0.05 | J10: =C10/$B10 -> 0.089479827 | K10: =D10/$B10 -> 0.072689913 | L10: =E10/$B10 -> 0.016789914 | M10: =F10/$B10 -> 0.039011754 | P10: =AVERAGE(C9:C10)/B10 -> 0.086438913 | Q10: 1238.5359 | R10: 317.64292 | T10: =R10/Q10 -> 0.25646646 | U10: 1543.8115 | W10: =E10/C10 -> 0.1876391 | X10: =F10/C10 -> 0.43598379
A11: 2004 | B11: 44810 | C11: =D11+E11 -> 4266.8114 | D11: 3530.2039 | E11: =E12*U11/U12 -> 736.60745 | F11: 1819.919 | G11: 0.05 | I11: 11500 | J11: =C11/$B11 -> 0.095220071 | K11: =D11/$B11 -> 0.07878161 | L11: =E11/$B11 -> 0.016438461 | M11: =F11/$B11 -> 0.040614126 | O11: =I11/$B11 -> 0.25663914 | P11: =AVERAGE(C10:C11)/B11 -> 0.087437644 | Q11: 1459.017 | R11: 360.90195 | T11: =R11/Q11 -> 0.24735965 | U11: 1697.9225 | W11: =E11/C11 -> 0.17263652 | X11: =F11/C11 -> 0.42652904
A12: 2005 | B12: 48520 | C12: =D12+E12 -> 4566.7319 | D12: 3780.1073 | E12: =E13*U12/U13 -> 786.62464 | F12: 2019.5016 | G12: 0.05 | H12: =H13/1.107 -> 6052.3939 | J12: =C12/$B12 -> 0.094120609 | K12: =D12/$B12 -> 0.077908229 | L12: =E12/$B12 -> 0.016212379 | M12: =F12/$B12 -> 0.041622044 | N12: =H12/$B12 -> 0.12474019 | P12: =AVERAGE(C11:C12)/B12 -> 0.091029919 | Q12: 1626.7653 | R12: 392.73626 | T12: =R12/Q12 -> 0.24142159 | U12: 1813.215 | W12: =E12/C12 -> 0.17225111 | X12: =F12/C12 -> 0.4422203
A13: 2006 | B13: 51690 | C13: =D13+E13 -> 5052.61 | D13: 4147.6764 | E13: =E14*U13/U14 -> 904.93363 | F13: 2422.1622 | G13: 0.05 | H13: 6700 | J13: =C13/$B13 -> 0.097748308 | K13: =D13/$B13 -> 0.08024137 | L13: =E13/$B13 -> 0.017506938 | M13: =F13/$B13 -> 0.046859396 | N13: =H13/$B13 -> 0.12961888 | P13: =AVERAGE(C12:C13)/B13 -> 0.093048384 | Q13: 1920.9335 | R13: 501.22868 | T13: =R13/Q13 -> 0.26092974 | U13: 2085.924 | W13: =E13/C13 -> 0.17910221 | X13: =F13/C13 -> 0.47938831
A14: 2007 | B14: 58340 | C14: =D14+E14 -> 6795.0723 | D14: 5658.8352 | E14: =E15*U14/U15 -> 1136.2371 | F14: 2911.7417 | G14: 0.05 | H14: 7300 | J14: =C14/$B14 -> 0.11647364 | K14: =D14/$B14 -> 0.096997518 | L14: =E14/$B14 -> 0.019476124 | M14: =F14/$B14 -> 0.049909869 | N14: =H14/$B14 -> 0.12512856 | P14: =AVERAGE(C13:C14)/B14 -> 0.10153996 | Q14: 2289.6137 | R14: 622.128 | T14: =R14/Q14 -> 0.27171745 | U14: 2619.0918 | W14: =E14/C14 -> 0.16721486 | X14: =F14/C14 -> 0.42850784
A15: 2008 | B15: 64000 | C15: =D15+E15 -> 5644.1316 | D15: 4384.1029 | E15: =E16*U15/U16 -> 1260.0287 | F15: 2135.3864 | G15: 0.1 | H15: 6700 | J15: =C15/$B15 -> 0.088189556 | K15: =D15/$B15 -> 0.068501608 | L15: =E15/$B15 -> 0.019687948 | M15: =F15/$B15 -> 0.033365412 | N15: =H15/$B15 -> 0.1046875 | P15: =AVERAGE(C14:C15)/B15 -> 0.09718128 | Q15: 1649.7491 | R15: 485.63727 | T15: =R15/Q15 -> 0.29437037 | U15: 2904.4385 | W15: =E15/C15 -> 0.2232458 | X15: =F15/C15 -> 0.37833746
A16: 2009 | B16: 60690 | C16: =D16+E16 -> 6305.3213 | D16: 5145.125 | E16: =E17*U16/U17 -> 1160.1962 | F16: 2358.6086 | G16: 0.1 | H16: 7400 | J16: =C16/$B16 -> 0.10389391 | K16: =D16/$B16 -> 0.084777147 | L16: =E16/$B16 -> 0.019116761 | M16: =F16/$B16 -> 0.038863216 | N16: =H16/$B16 -> 0.12193113 | P16: =AVERAGE(C15:C16)/B16 -> 0.098446637 | Q16: 2006.2416 | R16: 352.36701 | T16: =R16/Q16 -> 0.17563539 | U16: 2674.319 | W16: =E16/C16 -> 0.18400272 | X16: =F16/C16 -> 0.37406636
A17: 2010 | B17: 66400 | C17: =D17+E17 -> 5844.8574 | D17: 4702.0421 | E17: =E18*U17/U18 -> 1142.8153 | F17: 2301.2504 | G17: 0.1 | H17: 7800 | I17: 21000 | J17: =C17/$B17 -> 0.088024961 | K17: =D17/$B17 -> 0.070813887 | L17: =E17/$B17 -> 0.017211074 | M17: =F17/$B17 -> 0.034657385 | N17: =H17/$B17 -> 0.11746988 | O17: =I17/$B17 -> 0.31626506 | P17: =AVERAGE(C16:C17)/B17 -> 0.091492309 | Q17: 2004.4518 | R17: 296.79851 | T17: =R17/Q17 -> 0.14806966 | U17: 2634.255 | W17: =E17/C17 -> 0.19552493 | X17: =F17/C17 -> 0.39372224
A18: 2011 | B18: 73900 | C18: =D18+E18 -> 6563.066 | D18: 5401.5733 | E18: =E19*D18/D19 -> 1161.4927 | F18: 2251.6964 | G18: 0.1 | H18: 7800 | J18: =C18/$B18 -> 0.088810095 | K18: =D18/$B18 -> 0.073093008 | L18: =E18/$B18 -> 0.015717087 | M18: =F18/$B18 -> 0.030469505 | N18: =H18/$B18 -> 0.10554804 | P18: =AVERAGE(C17:C18)/B18 -> 0.083950768 | Q18: 1970.7454 | R18: 280.95105 | T18: =R18/Q18 -> 0.14256081 | U18: 2677.3075 | W18: =E18/C18 -> 0.17697411 | X18: =F18/C18 -> 0.34308605
A19: 2012 | B19: 75230 | C19: =D19+E19 -> 8219.9757 | D19: 6765.2528 | E19: =E20*D19/D20 -> 1454.7228 | F19: 2369.8748 | G19: 0.15 | H19: 8500 | J19: =C19/$B19 -> 0.1092646 | K19: =D19/$B19 -> 0.089927593 | L19: =E19/$B19 -> 0.019337004 | M19: =F19/$B19 -> 0.031501726 | N19: =H19/$B19 -> 0.11298684 | P19: =AVERAGE(C18:C19)/B19 -> 0.098252304 | Q19: 2149.3225 | R19: 220.5523 | T19: =R19/Q19 -> 0.1026148 | U19: 2677.3075 | W19: =E19/C19 -> 0.17697411 | X19: =F19/C19 -> 0.28830679
A20: 2013 | B20: 77380 | C20: =D20+E20 -> 8475.8163 | D20: 6975.8163 | E20: 1500 | F20: 2423.484 | G20: 0.2 | H20: 8900 | J20: =C20/$B20 -> 0.10953497 | K20: =D20/$B20 -> 0.09015012 | L20: =E20/$B20 -> 0.019384854 | M20: =F20/$B20 -> 0.031319256 | N20: =H20/$B20 -> 0.1150168 | P20: =AVERAGE(C19:C20)/B20 -> 0.10788183 | Q20: 2226.1948 | R20: 197.2892 | T20: =R20/Q20 -> 0.088621712 | W20: =E20/C20 -> 0.17697411 | X20: =F20/C20 -> 0.28592928
A21: 2014 | B21: 79420 | C21: =J21*B21 -> 9523.3891 | D21: 7714.0513 | E21: =C21-D21 -> 1809.3377 | F21: 2341.8949 | G21: 0.2 | H21: 10000 | J21: =J20*N21/N20 -> 0.11991172 | K21: =D21/$B21 -> 0.097129833 | L21: =E21/$B21 -> 0.022781891 | M21: =F21/$B21 -> 0.029487471 | N21: =H21/$B21 -> 0.12591287 | P21: =AVERAGE(C20:C21)/B21 -> 0.11331658 | Q21: 2174.4505 | R21: 167.44441 | T21: =R21/Q21 -> 0.077005391 | W21: =E21/C21 -> 0.18998885 | X21: =F21/C21 -> 0.24590982
A22: 2015 | B22: 75120 | C22: =C21*H22/H21 -> 9523.3891 | D22: 7107.907 | E22: =$C22*E21/$C21 -> 1809.3377 | F22: 2216.8993 | G22: 0.2 | H22: 10000 | J22: =J21*N22/N21 -> 0.12677568 | K22: =D22/$B22 -> 0.0946207 | L22: =E22/$B22 -> 0.024085966 | M22: =F22/$B22 -> 0.029511439 | N22: =H22/$B22 -> 0.13312034 | P22: =AVERAGE(C21:C22)/B22 -> 0.12677568 | Q22: 2020.828 | R22: 143.00458 | T22: =R22/Q22 -> 0.070765339 | W22: =E22/C22 -> 0.18998885 | X22: =F22/C22 -> 0.2327847
A23: 2016 | B23: 76440 | C23: =D23+E23 -> 7905.564 | D23: 6301.4995 | E23: =E22*$D23/$D22 -> 1604.0645 | F23: =Q23+R23 -> 2128.9411 | H23: 10300 | J23: =C23/$B23 -> 0.10342182 | K23: =D23/$B23 -> 0.082437199 | L23: =E23/$B23 -> 0.020984621 | M23: =F23/$B23 -> 0.027851139 | N23: =H23/$B23 -> 0.13474621 | P23: =AVERAGE(C22:C23)/B23 -> 0.11400414 | Q23: 1984.3516 | R23: 144.58946 | T23: =R23/Q23 -> 0.072864839 | W23: =E23/C23 -> 0.20290323 | X23: =F23/C23 -> 0.26929655
A24: 2017 | B24: 81200 | C24: =D24+E24 -> 9429.1896 | D24: 7515.9766 | E24: =E23*$D24/$D23 -> 1913.213 | F24: =Q24+R24 -> 2444.343 | H24: 8200 | J24: =C24/$B24 -> 0.11612302 | K24: =D24/$B24 -> 0.092561288 | L24: =E24/$B24 -> 0.023561737 | M24: =F24/$B24 -> 0.030102747 | N24: =H24/$B24 -> 0.10098522 | P24: =AVERAGE(C23:C24)/B24 -> 0.10674109 | Q24: 2268.1587 | R24: 176.18438 | T24: =R24/Q24 -> 0.077677275 | W24: =E24/C24 -> 0.20290323 | X24: =F24/C24 -> 0.25923151
A25: 2018 | B25: 86030 | C25: =D25+E25 -> 8765.7848 | D25: 6987.1787 | E25: =E24*$D25/$D24 -> 1778.606 | F25: =Q25+R25 -> 2281.5676 | H25: 8700 | I25: 9900 | J25: =C25/$B25 -> 0.10189219 | K25: =D25/$B25 -> 0.081217932 | L25: =E25/$B25 -> 0.020674254 | M25: =F25/$B25 -> 0.026520604 | N25: =H25/$B25 -> 0.10112751 | P25: =AVERAGE(C24:C25)/B25 -> 0.10574785 | Q25: 2076.2713 | R25: 205.29628 | T25: =R25/Q25 -> 0.098877387 | W25: =E25/C25 -> 0.20290323 | X25: =F25/C25 -> 0.26028104
A26: 2019 | B26: 87330 | C26: =D26+E26 -> 10740.665 | D26: 8561.3498 | E26: =E25*$D26/$D25 -> 2179.3157 | F26: =Q26+R26 -> 2594.5729 | H26: 9600 | J26: =C26/$B26 -> 0.12298941 | K26: =D26/$B26 -> 0.098034464 | L26: =E26/$B26 -> 0.024954949 | M26: =F26/$B26 -> 0.029709984 | N26: =H26/$B26 -> 0.10992786 | P26: =AVERAGE(C25:C26)/B26 -> 0.11168241 | Q26: 2339.1093 | R26: 255.46357 | T26: =R26/Q26 -> 0.10921404 | W26: =E26/C26 -> 0.20290323 | X26: =F26/C26 -> 0.24156538
A27: 2020 | B27: 85050 | C27: =D27+E27 -> 12856.722 | D27: 10248.052 | E27: =E26*$D27/$D26 -> 2608.6705 | F27: =Q27+R27 -> 2761.3611 | J27: =C27/$B27 -> 0.15116663 | K27: =D27/$B27 -> 0.12049444 | L27: =E27/$B27 -> 0.030672198 | M27: =F27/$B27 -> 0.032467503 | P27: =AVERAGE(C26:C27)/B27 -> 0.13872656 | Q27: 2587.9467 | R27: 173.41445 | T27: =R27/Q27 -> 0.067008508 | W27: =E27/C27 -> 0.20290323 | X27: =F27/C27 -> 0.21477956
A28: 2021 | B28: 96590 | C28: =D28+E28 -> 14033.606 | D28: 11186.142 | E28: =E27*$D28/$D27 -> 2847.464 | F28: =Q28+R28 -> 3026.4719 | J28: =C28/$B28 -> 0.14529047 | K28: =D28/$B28 -> 0.11581056 | L28: =E28/$B28 -> 0.029479905 | M28: =F28/$B28 -> 0.03133318 | P28: =AVERAGE(C27:C28)/B28 -> 0.1391983 | Q28: 2863.4094 | R28: 163.06251 | T28: =R28/Q28 -> 0.056946979 | W28: =E28/C28 -> 0.20290323 | X28: =F28/C28 -> 0.21565889
A29: 2022 | B29: 101100 | C29: =D29+E29 -> 12387.728 | D29: =D28-0.177*7412 -> 9874.2181 | E29: =E28*$D29/$D28 -> 2513.5101 | F29: =Q29+R29 -> 2655.1 | H29: 12000 | J29: =C29/$B29 -> 0.12252946 | K29: =D29/$B29 -> 0.097667835 | L29: =E29/$B29 -> 0.024861623 | M29: =F29/$B29 -> 0.026262117 | N29: =H29/$B29 -> 0.11869436 | P29: =AVERAGE(C28:C29)/B29 -> 0.13066931 | Q29: 2383.1 | R29: 272 | T29: =R29/Q29 -> 0.11413705
A31: Notes: Stocks are as at December 31st of each year. Source: Portfolio securities from Zucman (2015), file "Global offshore wealth" available at http://gabriel-zucman.eu/files/Zucman2015MissingWealth.xlsx, Table A.3, which updated the Appendix of Zucman (QJE 2013). The series in Zucman (2015) are very close to those in the QJE article, except in 2008 (latest data point in the QJE article) and 2006, where the updated series are about 5% lower. The 2008 decline was due to the availability of updated IIP data; but the 2006 revision is not consistent with the Swiss data (it implies an implausibly high Swiss share of 55%), therefore we correct the 2006 data point. Bank deposits: we use Zucman's (2015) number for end-2013, $1500 billion, and assume that bank deposits follow the total amount of BIS deposits in banking havens.
A34: Notes on BCG: The 2017 global wealth report indicates $10.3T in global offshore wealth in 2016 (exhibit 5). The 2018 report indicates that "global offshore wealth in 2017 was around $8.2 trillion, 6% higher than in the previous year in US dollar terms" (p. 11), implying $7.7 trillion in 2016, 25% less than estimated in the 2017 report. Thus it seems the methodology changed in the 2018 report. The 2018 report writes that offshore wealth is estimated based on "data published by financial centers and by the Bank of (sic) International Settlements, as well as from data generated by BCG project experience." (p. 4). Earlier editions of the report did not mention the BIS. AJZ paper "Who owns the wealth in tax havens?" was released as an NBER working paper in September 2017. Source for BCG reports: https://www.bcg.com/publications/2023/global-wealth-report-resetting-the-course

Sheet T.A2
AS1: Share household deposit
A2: Table A2: Where is the world's offshore wealth located? | P2: BIS liabilities to non-banks
B3: Share of offshore wealth | I3: billion of current US$ | P3: Non-CH havens | Q3: American havens | R3: Asian havens | S3: European havens | U3: AN | V3: AT | W3: BE | X3: BH | Y3: BM | Z3: BS | AA3: CH | AB3: CL | AC3: CW | AD3: CY | AE3: GB | AF3: GG | AG3: HK | AH3: IM | AI3: JE | AJ3: KY | AK3: LU | AL3: MO | AM3: MY | AN3: PA | AO3: SG | AP3: US | AR3: AN | AS3: AT | AT3: BE | AU3: BH | AV3: BM | AW3: BS | AX3: CH | AY3: CL | AZ3: CW | BA3: CY | BB3: GB | BC3: GG | BD3: HK | BE3: IM | BF3: JE | BG3: KY | BH3: LU | BI3: MO | BJ3: MY | BK3: PA | BL3: SG | BM3: US
B4: Total offshore wealth | C4: Switzerland | D4: Tax havens other than Switzerland | E4: Of which: American tax havens | F4: Of which: Asian tax havens | G4: Of which: European tax havens | I4: Total offshore wealth | J4: Switzerland | K4: Tax havens other than Switzerland | L4: Of which: American tax havens | M4: Of which: Asian tax havens | N4: Of which: European tax havens
A5: 2001 | B5: =T.A1!C8/T.A1!$C8 -> 1 | C5: =T.A1!F8/T.A1!$C8 -> 0.38388394 | D5: =1-C5 -> 0.61611606 | E5: =$D5*Q5/$P5 -> 0.098106889 | F5: =$D5*R5/$P5 -> 0.19368153 | G5: =$D5*S5/$P5 -> 0.32432764 | H5: 2001 | I5: =T.A1!C8 -> 3311.5496 | J5: =T.A1!F8 -> 1271.2507 | K5: =I5-J5 -> 2040.2989 | L5: =E5*$I5 -> 324.88583 | M5: =F5*$I5 -> 641.38599 | N5: =G5*$I5 -> 1074.0271 | P5: =Q5+R5+S5 -> 685.88496 | Q5: =AJ5+AN5+AB5+AP5 -> 109.2165 | R5: =X5+Y5+Z5+AG5+AL5+AM5+AO5+U5+AC5 -> 215.614 | S5: =V5+W5+AE5+AF5+AH5+AI5+AK5+AD5 -> 361.05446 | U5: =AR5*bisdepbyhaven!B26/1000 -> 5.369 | V5: =AS5*bisdepbyhaven!C26/1000 -> 2.8488 | W5: =AT5*bisdepbyhaven!D26/1000 -> 33.4125 | X5: =AU5*bisdepbyhaven!E26/1000 -> 16.968 | Y5: =AV5*bisdepbyhaven!F26/1000 -> 0 | Z5: =AW5*bisdepbyhaven!G26/1000 -> 62.7375 | AA5: =AX5*bisdepbyhaven!H26/1000 -> 290.169 | AB5: =AY5*bisdepbyhaven!I26/1000 -> 0 | AC5: =AZ5*bisdepbyhaven!J26/1000 -> 0 | AD5: =AD6*(V5+W5+AE5+AF5+AH5+AI5+AK5)/(V6+W6+AE6+AF6+AH6+AI6+AK6) -> 12.624761 | AE5: =BB5*bisdepbyhaven!L26/1000 -> 46.4094 | AF5: =BC5*bisdepbyhaven!M26/1000 -> 46.278 | AG5: =BD5*bisdepbyhaven!N26/1000 -> 51.3513 | AH5: =BE5*bisdepbyhaven!O26/1000 -> 22.052 | AI5: =BF5*bisdepbyhaven!P26/1000 -> 70.476 | AJ5: =BG5*bisdepbyhaven!Q26/1000 -> 90.8799 | AK5: =BH5*bisdepbyhaven!R26/1000 -> 126.953 | AL5: =BI5*bisdepbyhaven!S26/1000 -> 0 | ... AP5: =BM5*bisdepbyhaven!W26/1000 -> 18.3366 | AR5: 0.7 | AS5: 0.3 | AT5: 0.3 | AU5: 0.7 | AV5: 0.7 | AW5: 0.7 | AX5: 1 | AY5: 0 | AZ5: 0.7 | BA5: 1 | BB5: 0.1 | BC5: 1 | BD5: 0.7 | BE5: 1 | BF5: 1 | BG5: 0.3 | BH5: 1 | BI5: 0.7 | BJ5: 0.7 | BK5: 1 | BL5: 0.7 | BM5: 0.1
A6: 2002 | B6: =T.A1!C9/T.A1!$C9 -> 1 | C6: =T.A1!F9/T.A1!$C9 -> 0.38549383 | D6: =1-C6 -> 0.61450617 | E6: =$D6*Q6/$P6 -> 0.12822556 | F6: =$D6*R6/$P6 -> 0.16095221 | G6: =$D6*S6/$P6 -> 0.32532841 | H6: 2002 | I6: =T.A1!C9 -> 3326.7462 | J6: =T.A1!F9 -> 1282.4401 | K6: =I6-J6 -> 2044.3061 | L6: =E6*$I6 -> 426.57388 | M6: =F6*$I6 -> 535.44714 | N6: =G6*$I6 -> 1082.2851 | P6: =Q6+R6+S6 -> 741.40537 | Q6: =AJ6+AN6+AB6+AP6 -> 154.7049 | R6: =X6+Y6+Z6+AG6+AL6+AM6+AO6+U6+AC6 -> 194.1898 | S6: =V6+W6+AE6+AF6+AH6+AI6+AK6+AD6 -> 392.51067 | U6: =AR6*bisdepbyhaven!B27/1000 -> 6.0984 | V6: =AS6*bisdepbyhaven!C27/1000 -> 4.0722 | W6: =AT6*bisdepbyhaven!D27/1000 -> 43.392 | X6: =AU6*bisdepbyhaven!E27/1000 -> 14.0749 | Y6: =AV6*bisdepbyhaven!F27/1000 -> 1.2432 | Z6: =AW6*bisdepbyhaven!G27/1000 -> 48.0662 | AA6: =AX6*bisdepbyhaven!H27/1000 -> 305.081 | AB6: =AY6*bisdepbyhaven!I27/1000 -> 0 | AC6: =AZ6*bisdepbyhaven!J27/1000 -> 0 | AD6: =AD7*(V6+W6+AE6+AF6+AH6+AI6+AK6)/(V7+W7+AE7+AF7+AH7+AI7+AK7) -> 13.72467 | AE6: =BB6*bisdepbyhaven!L27/1000 -> 55.7498 | AF6: =BC6*bisdepbyhaven!M27/1000 -> 35.534 | AG6: =BD6*bisdepbyhaven!N27/1000 -> 42.6601 | AH6: =BE6*bisdepbyhaven!O27/1000 -> 25.227 | AI6: =BF6*bisdepbyhaven!P27/1000 -> 81.424 | AJ6: =BG6*bisdepbyhaven!Q27/1000 -> 133.6629 | AK6: =BH6*bisdepbyhaven!R27/1000 -> 133.387 | AL6: =BI6*bisdepbyhaven!S27/1000 -> 0 | ... AP6: =BM6*bisdepbyhaven!W27/1000 -> 21.029 | AR6: 0.7 | AS6: 0.3 | AT6: 0.3 | AU6: 0.7 | AV6: 0.7 | AW6: 0.7 | AX6: 1 | AY6: 0 | AZ6: 0.7 | BA6: 1 | BB6: 0.1 | BC6: 1 | BD6: 0.7 | BE6: 1 | BF6: 1 | BG6: 0.3 | BH6: 1 | BI6: 0.7 | BJ6: 0.7 | BK6: 1 | BL6: 0.7 | BM6: 0.1
A7: 2003 | B7: =T.A1!C10/T.A1!$C10 -> 1 | C7: =T.A1!F10/T.A1!$C10 -> 0.43598379 | D7: =1-C7 -> 0.56401621 | E7: =$D7*Q7/$P7 -> 0.11505808 | F7: =$D7*R7/$P7 -> 0.13861401 | G7: =$D7*S7/$P7 -> 0.31034412 | H7: 2003 | I7: =T.A1!C10 -> 3569.3503 | J7: =T.A1!F10 -> 1556.1789 | K7: =I7-J7 -> 2013.1714 | L7: =E7*$I7 -> 410.6826 | M7: =F7*$I7 -> 494.76194 | N7: =G7*$I7 -> 1107.7269 | P7: =Q7+R7+S7 -> 911.65432 | Q7: =AJ7+AN7+AB7+AP7 -> 185.9755 | R7: =X7+Y7+Z7+AG7+AL7+AM7+AO7+U7+AC7 -> 224.0504 | S7: =V7+W7+AE7+AF7+AH7+AI7+AK7+AD7 -> 501.62842 | U7: =AR7*bisdepbyhaven!B28/1000 -> 6.8446 | V7: =AS7*bisdepbyhaven!C28/1000 -> 5.3745 | W7: =AT7*bisdepbyhaven!D28/1000 -> 53.5794 | X7: =AU7*bisdepbyhaven!E28/1000 -> 14.777 | Y7: =AV7*bisdepbyhaven!F28/1000 -> 1.4469 | Z7: =AW7*bisdepbyhaven!G28/1000 -> 60.1426 | AA7: =AX7*bisdepbyhaven!H28/1000 -> 323.752 | AB7: =AY7*bisdepbyhaven!I28/1000 -> 0 | AC7: =AZ7*bisdepbyhaven!J28/1000 -> 0 | AD7: =AD8*(V7+W7+AE7+AF7+AH7+AI7+AK7)/(V8+W8+AE8+AF8+AH8+AI8+AK8) -> 17.54012 | AE7: =BB7*bisdepbyhaven!L28/1000 -> 75.6394 | AF7: =BC7*bisdepbyhaven!M28/1000 -> 43.687 | AG7: =BD7*bisdepbyhaven!N28/1000 -> 50.8753 | AH7: =BE7*bisdepbyhaven!O28/1000 -> 28.919 | AI7: =BF7*bisdepbyhaven!P28/1000 -> 114.642 | AJ7: =BG7*bisdepbyhaven!Q28/1000 -> 138.0483 | AK7: =BH7*bisdepbyhaven!R28/1000 -> 162.247 | AL7: =BI7*bisdepbyhaven!S28/1000 -> 1.4371 | ... AP7: =BM7*bisdepbyhaven!W28/1000 -> 42.9252 | AR7: 0.7 | AS7: 0.3 | AT7: 0.3 | AU7: 0.7 | AV7: 0.7 | AW7: 0.7 | AX7: 1 | AY7: 0 | AZ7: 0.7 | BA7: 1 | BB7: 0.1 | BC7: 1 | BD7: 0.7 | BE7: 1 | BF7: 1 | BG7: 0.3 | BH7: 1 | BI7: 0.7 | BJ7: 0.7 | BK7: 1 | BL7: 0.7 | BM7: 0.1
A8: 2004 | B8: =T.A1!C11/T.A1!$C11 -> 1 | C8: =T.A1!F11/T.A1!$C11 -> 0.42652904 | D8: =1-C8 -> 0.57347096 | E8: =$D8*Q8/$P8 -> 0.12259008 | F8: =$D8*R8/$P8 -> 0.13626942 | G8: =$D8*S8/$P8 -> 0.31461146 | H8: 2004 | I8: =T.A1!C11 -> 4266.8114 | J8: =T.A1!F11 -> 1819.919 | K8: =I8-J8 -> 2446.8924 | L8: =E8*$I8 -> 523.06875 | M8: =F8*$I8 -> 581.43592 | N8: =G8*$I8 -> 1342.3877 | P8: =Q8+R8+S8 -> 1004.1381 | Q8: =AJ8+AN8+AB8+AP8 -> 214.6532 | R8: =X8+Y8+Z8+AG8+AL8+AM8+AO8+U8+AC8 -> 238.6055 | S8: =V8+W8+AE8+AF8+AH8+AI8+AK8+AD8 -> 550.87945 | U8: =AR8*bisdepbyhaven!B29/1000 -> 7.8841 | V8: =AS8*bisdepbyhaven!C29/1000 -> 6.078 | W8: =AT8*bisdepbyhaven!D29/1000 -> 65.0436 | X8: =AU8*bisdepbyhaven!E29/1000 -> 18.2238 | Y8: =AV8*bisdepbyhaven!F29/1000 -> 1.841 | Z8: =AW8*bisdepbyhaven!G29/1000 -> 62.1999 | AA8: =AX8*bisdepbyhaven!H29/1000 -> 354.136 | AB8: =AY8*bisdepbyhaven!I29/1000 -> 0 | AC8: =AZ8*bisdepbyhaven!J29/1000 -> 0 | AD8: =AD9*(V8+W8+AE8+AF8+AH8+AI8+AK8)/(V9+W9+AE9+AF9+AH9+AI9+AK9) -> 19.26225 | AE8: =BB8*bisdepbyhaven!L29/1000 -> 96.7606 | AF8: =BC8*bisdepbyhaven!M29/1000 -> 48.533 | AG8: =BD8*bisdepbyhaven!N29/1000 -> 59.5882 | AH8: =BE8*bisdepbyhaven!O29/1000 -> 33.334 | AI8: =BF8*bisdepbyhaven!P29/1000 -> 103.779 | AJ8: =BG8*bisdepbyhaven!Q29/1000 -> 145.9701 | AK8: =BH8*bisdepbyhaven!R29/1000 -> 178.089 | AL8: =BI8*bisdepbyhaven!S29/1000 -> 1.6443 | ... AP8: =BM8*bisdepbyhaven!W29/1000 -> 62.7821 | AR8: 0.7 | AS8: 0.3 | AT8: 0.3 | AU8: 0.7 | AV8: 0.7 | AW8: 0.7 | AX8: 1 | AY8: 0 | AZ8: 0.7 | BA8: 1 | BB8: 0.1 | BC8: 1 | BD8: 0.7 | BE8: 1 | BF8: 1 | BG8: 0.3 | BH8: 1 | BI8: 0.7 | BJ8: 0.7 | BK8: 1 | BL8: 0.7 | BM8: 0.1
A9: 2005 | B9: =T.A1!C12/T.A1!$C12 -> 1 | C9: =T.A1!F12/T.A1!$C12 -> 0.4422203 | D9: =1-C9 -> 0.5577797 | E9: =$D9*Q9/$P9 -> 0.10903351 | F9: =$D9*R9/$P9 -> 0.14660505 | G9: =$D9*S9/$P9 -> 0.30214114 | H9: 2005 | I9: =T.A1!C12 -> 4566.7319 | J9: =T.A1!F12 -> 2019.5016 | K9: =I9-J9 -> 2547.2304 | L9: =E9*$I9 -> 497.92682 | M9: =F9*$I9 -> 669.50597 | N9: =G9*$I9 -> 1379.7976 | P9: =Q9+R9+S9 -> 1068.8578 | Q9: =AJ9+AN9+AB9+AP9 -> 208.9379 | R9: =X9+Y9+Z9+AG9+AL9+AM9+AO9+U9+AC9 -> 280.9352 | S9: =V9+W9+AE9+AF9+AH9+AI9+AK9+AD9 -> 578.98469 | U9: =AR9*bisdepbyhaven!B30/1000 -> 7.9989 | V9: =AS9*bisdepbyhaven!C30/1000 -> 12.0786 | W9: =AT9*bisdepbyhaven!D30/1000 -> 69.8061 | X9: =AU9*bisdepbyhaven!E30/1000 -> 23.6726 | Y9: =AV9*bisdepbyhaven!F30/1000 -> 2.0244 | Z9: =AW9*bisdepbyhaven!G30/1000 -> 78.9026 | AA9: =AX9*bisdepbyhaven!H30/1000 -> 355.416 | AB9: =AY9*bisdepbyhaven!I30/1000 -> 0 | AC9: =AZ9*bisdepbyhaven!J30/1000 -> 0 | AD9: =AD10*(V9+W9+AE9+AF9+AH9+AI9+AK9)/(V10+W10+AE10+AF10+AH10+AI10+AK10) -> 20.244988 | AE9: =BB9*bisdepbyhaven!L30/1000 -> 102.784 | AF9: =BC9*bisdepbyhaven!M30/1000 -> 50.342 | AG9: =BD9*bisdepbyhaven!N30/1000 -> 67.2504 | AH9: =BE9*bisdepbyhaven!O30/1000 -> 40.409 | AI9: =BF9*bisdepbyhaven!P30/1000 -> 129.167 | AJ9: =BG9*bisdepbyhaven!Q30/1000 -> 143.0043 | AK9: =BH9*bisdepbyhaven!R30/1000 -> 154.153 | AL9: =BI9*bisdepbyhaven!S30/1000 -> 3.9613 | ... AP9: =BM9*bisdepbyhaven!W30/1000 -> 59.5646 | AR9: 0.7 | AS9: 0.3 | AT9: 0.3 | AU9: 0.7 | AV9: 0.7 | AW9: 0.7 | AX9: 1 | AY9: 0 | AZ9: 0.7 | BA9: 1 | BB9: 0.1 | BC9: 1 | BD9: 0.7 | BE9: 1 | BF9: 1 | BG9: 0.3 | BH9: 1 | BI9: 0.7 | BJ9: 0.7 | BK9: 1 | BL9: 0.7 | BM9: 0.1
A10: 2006 | B10: =T.A1!C13/T.A1!$C13 -> 1 | C10: =T.A1!F13/T.A1!$C13 -> 0.47938831 | D10: =1-C10 -> 0.52061169 | E10: =$D10*Q10/$P10 -> 0.10650635 | F10: =$D10*R10/$P10 -> 0.13786515 | G10: =$D10*S10/$P10 -> 0.27624019 | H10: 2006 | I10: =T.A1!C13 -> 5052.61 | J10: =T.A1!F13 -> 2422.1622 | K10: =I10-J10 -> 2630.4479 | L10: =E10*$I10 -> 538.13506 | M10: =F10*$I10 -> 696.57885 | N10: =G10*$I10 -> 1395.734 | P10: =Q10+R10+S10 -> 1329.299 | Q10: =AJ10+AN10+AB10+AP10 -> 271.947 | R10: =X10+Y10+Z10+AG10+AL10+AM10+AO10+U10+AC10 -> 352.0167 | S10: =V10+W10+AE10+AF10+AH10+AI10+AK10+AD10 -> 705.33531 | U10: =AR10*bisdepbyhaven!B31/1000 -> 7.0784 | V10: =AS10*bisdepbyhaven!C31/1000 -> 15.7653 | W10: =AT10*bisdepbyhaven!D31/1000 -> 72.528 | X10: =AU10*bisdepbyhaven!E31/1000 -> 36.4105 | Y10: =AV10*bisdepbyhaven!F31/1000 -> 1.8382 | Z10: =AW10*bisdepbyhaven!G31/1000 -> 99.6772 | AA10: =AX10*bisdepbyhaven!H31/1000 -> 443.017 | AB10: =AY10*bisdepbyhaven!I31/1000 -> 0 | AC10: =AZ10*bisdepbyhaven!J31/1000 -> 0 | AD10: =AD11*(V10+W10+AE10+AF10+AH10+AI10+AK10)/(V11+W11+AE11+AF11+AH11+AI11+AK11) -> 24.663009 | AE10: =BB10*bisdepbyhaven!L31/1000 -> 125.996 | AF10: =BC10*bisdepbyhaven!M31/1000 -> 57.573 | AG10: =BD10*bisdepbyhaven!N31/1000 -> 82.3326 | AH10: =BE10*bisdepbyhaven!O31/1000 -> 47.213 | AI10: =BF10*bisdepbyhaven!P31/1000 -> 161.061 | AJ10: =BG10*bisdepbyhaven!Q31/1000 -> 174.1125 | AK10: =BH10*bisdepbyhaven!R31/1000 -> 200.536 | AL10: =BI10*bisdepbyhaven!S31/1000 -> 5.0281 | ... AP10: =BM10*bisdepbyhaven!W31/1000 -> 90.0635 | AR10: 0.7 | AS10: 0.3 | AT10: 0.3 | AU10: 0.7 | AV10: 0.7 | AW10: 0.7 | AX10: 1 | AY10: 0 | AZ10: 0.7 | BA10: 1 | BB10: 0.1 | BC10: 1 | BD10: 0.7 | BE10: 1 | BF10: 1 | BG10: 0.3 | BH10: 1 | BI10: 0.7 | BJ10: 0.7 | BK10: 1 | BL10: 0.7 | BM10: 0.1
A11: 2007 | B11: =T.A1!C14/T.A1!$C14 -> 1 | C11: =T.A1!F14/T.A1!$C14 -> 0.42850784 | D11: =1-C11 -> 0.57149216 | E11: =$D11*Q11/$P11 -> 0.11839624 | F11: =$D11*R11/$P11 -> 0.15765433 | G11: =$D11*S11/$P11 -> 0.29544159 | H11: 2007 | I11: =T.A1!C14 -> 6795.0723 | J11: =T.A1!F14 -> 2911.7417 | K11: =I11-J11 -> 3883.3306 | L11: =E11*$I11 -> 804.51101 | M11: =F11*$I11 -> 1071.2726 | N11: =G11*$I11 -> 2007.547 | P11: =Q11+R11+S11 -> 1684.825 | Q11: =AJ11+AN11+AB11+AP11 -> 349.0458 | R11: =X11+Y11+Z11+AG11+AL11+AM11+AO11+U11+AC11 -> 464.7832 | S11: =V11+W11+AE11+AF11+AH11+AI11+AK11+AD11 -> 870.99596 | U11: =AR11*bisdepbyhaven!B32/1000 -> 8.5862 | V11: =AS11*bisdepbyhaven!C32/1000 -> 19.4778 | W11: =AT11*bisdepbyhaven!D32/1000 -> 97.3302 | X11: =AU11*bisdepbyhaven!E32/1000 -> 45.591 | Y11: =AV11*bisdepbyhaven!F32/1000 -> 1.4553 | Z11: =AW11*bisdepbyhaven!G32/1000 -> 119.6041 | AA11: =AX11*bisdepbyhaven!H32/1000 -> 547.651 | AB11: =AY11*bisdepbyhaven!I32/1000 -> 0 | AC11: =AZ11*bisdepbyhaven!J32/1000 -> 0 | AD11: =AD12*(V11+W11+AE11+AF11+AH11+AI11+AK11)/(V12+W12+AE12+AF12+AH12+AI12+AK12) -> 30.455559 | AE11: =BB11*bisdepbyhaven!L32/1000 -> 168.6244 | AF11: =BC11*bisdepbyhaven!M32/1000 -> 69.15 | AG11: =BD11*bisdepbyhaven!N32/1000 -> 113.1438 | AH11: =BE11*bisdepbyhaven!O32/1000 -> 57.917 | AI11: =BF11*bisdepbyhaven!P32/1000 -> 220.415 | AJ11: =BG11*bisdepbyhaven!Q32/1000 -> 231.1692 | AK11: =BH11*bisdepbyhaven!R32/1000 -> 207.626 | AL11: =BI11*bisdepbyhaven!S32/1000 -> 6.6045 | ... AP11: =BM11*bisdepbyhaven!W32/1000 -> 107.7556 | AR11: 0.7 | AS11: 0.3 | AT11: 0.3 | AU11: 0.7 | AV11: 0.7 | AW11: 0.7 | AX11: 1 | AY11: 0 | AZ11: 0.7 | BA11: 1 | BB11: 0.1 | BC11: 1 | BD11: 0.7 | BE11: 1 | BF11: 1 | BG11: 0.3 | BH11: 1 | BI11: 0.7 | BJ11: 0.7 | BK11: 1 | BL11: 0.7 | BM11: 0.1
A12: 2008 | B12: =T.A1!C15/T.A1!$C15 -> 1 | C12: =T.A1!F15/T.A1!$C15 -> 0.37833746 | D12: =1-C12 -> 0.62166254 | E12: =$D12*Q12/$P12 -> 0.16097127 | F12: =$D12*R12/$P12 -> 0.18710504 | G12: =$D12*S12/$P12 -> 0.27358623 | H12: 2008 | I12: =T.A1!C15 -> 5644.1316 | J12: =T.A1!F15 -> 2135.3864 | K12: =I12-J12 -> 3508.7452 | L12: =E12*$I12 -> 908.54305 | M12: =F12*$I12 -> 1056.0455 | N12: =G12*$I12 -> 1544.1567 | P12: =Q12+R12+S12 -> 1515.8293 | Q12: =AJ12+AN12+AB12+AP12 -> 392.5039 | R12: =X12+Y12+Z12+AG12+AL12+AM12+AO12+U12+AC12 -> 456.2271 | S12: =V12+W12+AE12+AF12+AH12+AI12+AK12+AD12 -> 667.0983 | U12: =AR12*bisdepbyhaven!B33/1000 -> 8.0871 | V12: =AS12*bisdepbyhaven!C33/1000 -> 12.9142 | W12: =AT12*bisdepbyhaven!D33/1000 -> 70.9866 | X12: =AU12*bisdepbyhaven!E33/1000 -> 43.0899 | Y12: =AV12*bisdepbyhaven!F33/1000 -> 1.1396 | Z12: =AW12*bisdepbyhaven!G33/1000 -> 125.8656 | AA12: =AX12*bisdepbyhaven!H33/1000 -> 509.691 | AB12: =AY12*bisdepbyhaven!I33/1000 -> 0 | ... AP12: =BM12*bisdepbyhaven!W33/1000 -> 100.4023 | AR12: 0.7 | AS12: 0.2 | AT12: 0.2 | AU12: 0.7 | AV12: 0.7 | AW12: 0.7 | AX12: 1 | AY12: 0 | AZ12: 0.7 | BA12: 1 | BB12: 0.1 | BC12: 1 | BD12: 0.7 | BE12: 1 | BF12: 1 | BG12: 0.3 | BH12: 1 | BI12: 0.7 | BJ12: 0.7 | BK12: 1 | BL12: 0.7 | BM12: 0.1
A13: 2009 | B13: =T.A1!C16/T.A1!$C16 -> 1 | C13: =T.A1!F16/T.A1!$C16 -> 0.37406636 | D13: =1-C13 -> 0.62593364 | E13: =$D13*Q13/$P13 -> 0.15787685 | F13: =$D13*R13/$P13 -> 0.20113498 | G13: =$D13*S13/$P13 -> 0.26692181 | H13: 2009 | I13: =T.A1!C16 -> 6305.3213 | J13: =T.A1!F16 -> 2358.6086 | K13: =I13-J13 -> 3946.7127 | L13: =E13*$I13 -> 995.46424 | M13: =F13*$I13 -> 1268.2207 | N13: =G13*$I13 -> 1683.0277 | P13: =Q13+R13+S13 -> 1397.0093 | Q13: =AJ13+AN13+AB13+AP13 -> 352.3623 | R13: =X13+Y13+Z13+AG13+AL13+AM13+AO13+U13+AC13 -> 448.9093 | S13: =V13+W13+AE13+AF13+AH13+AI13+AK13+AD13 -> 595.73765 | U13: =AR13*bisdepbyhaven!B34/1000 -> 8.1851 | V13: =AS13*bisdepbyhaven!C34/1000 -> 9.98745 | W13: =AT13*bisdepbyhaven!D34/1000 -> 47.8659 | X13: =AU13*bisdepbyhaven!E34/1000 -> 40.7064 | Y13: =AV13*bisdepbyhaven!F34/1000 -> 1.2488 | Z13: =AW13*bisdepbyhaven!G34/1000 -> 100.9134 | AA13: =AX13*bisdepbyhaven!H34/1000 -> 482.995 | AB13: =AY13*bisdepbyhaven!I34/1000 -> 0 | ... AP13: =BM13*bisdepbyhaven!W34/1000 -> 86.0459 | AR13: 0.7 | AS13: 0.15 | AT13: 0.15 | AU13: 0.7 | AV13: 0.7 | AW13: 0.7 | AX13: 1 | AY13: 0 | AZ13: 0.7 | BA13: 1 | BB13: 0.1 | BC13: 0.95 | BD13: 0.7 | BE13: =BE12-0.05 -> 0.95 | BF13: =BF12-0.05 -> 0.95 | BG13: 0.3 | BH13: 1 | BI13: 0.7 | BJ13: 0.7 | BK13: 1 | BL13: 0.7 | BM13: 0.1
A14: 2010 | B14: =T.A1!C17/T.A1!$C17 -> 1 | C14: =T.A1!F17/T.A1!$C17 -> 0.39372224 | D14: =1-C14 -> 0.60627776 | E14: =$D14*Q14/$P14 -> 0.16436941 | F14: =$D14*R14/$P14 -> 0.20557825 | G14: =$D14*S14/$P14 -> 0.23633009 | H14: 2010 | I14: =T.A1!C17 -> 5844.8574 | J14: =T.A1!F17 -> 2301.2504 | K14: =I14-J14 -> 3543.607 | L14: =E14*$I14 -> 960.71579 | M14: =F14*$I14 -> 1201.5756 | N14: =G14*$I14 -> 1381.3157 | P14: =Q14+R14+S14 -> 1388.1313 | Q14: =AJ14+AN14+AB14+AP14 -> 376.3396 | R14: =X14+Y14+Z14+AG14+AL14+AM14+AO14+U14+AC14 -> 470.6912 | S14: =V14+W14+AE14+AF14+AH14+AI14+AK14+AD14 -> 541.1005 | U14: =AR14*bisdepbyhaven!B35/1000 -> 0 | V14: =AS14*bisdepbyhaven!C35/1000 -> 6.2575 | W14: =AT14*bisdepbyhaven!D35/1000 -> 28.9305 | X14: =AU14*bisdepbyhaven!E35/1000 -> 44.9421 | Y14: =AV14*bisdepbyhaven!F35/1000 -> 1.3398 | Z14: =AW14*bisdepbyhaven!G35/1000 -> 107.4283 | AA14: =AX14*bisdepbyhaven!H35/1000 -> 457.894 | AB14: =AY14*bisdepbyhaven!I35/1000 -> 0 | ... AP14: =BM14*bisdepbyhaven!W35/1000 -> 88.5824 | AR14: 0.7 | AS14: 0.1 | AT14: 0.1 | AU14: 0.7 | AV14: 0.7 | AW14: 0.7 | AX14: 1 | AY14: 0 | AZ14: 0.7 | BA14: 1 | BB14: 0.1 | BC14: 0.9 | BD14: 0.7 | BE14: =BE13-0.05 -> 0.9 | BF14: =BF13-0.05 -> 0.9 | BG14: 0.3 | BH14: 1 | BI14: 0.7 | BJ14: 0.7 | BK14: 1 | BL14: 0.7 | BM14: 0.1
A15: 2011 | B15: =T.A1!C18/T.A1!$C18 -> 1 | C15: =T.A1!F18/T.A1!$C18 -> 0.34308605 | D15: =1-C15 -> 0.65691395 | E15: =$D15*Q15/$P15 -> 0.15925788 | F15: =$D15*R15/$P15 -> 0.2444979 | G15: =$D15*S15/$P15 -> 0.25315818 | H15: 2011 | I15: =T.A1!C18 -> 6563.066 | J15: =T.A1!F18 -> 2251.6964 | K15: =I15-J15 -> 4311.3696 | L15: =E15*$I15 -> 1045.22 | M15: =F15*$I15 -> 1604.6558 | N15: =G15*$I15 -> 1661.4938 | P15: =Q15+R15+S15 -> 1293.2856 | Q15: =AJ15+AN15+AB15+AP15 -> 313.5356 | R15: =X15+Y15+Z15+AG15+AL15+AM15+AO15+U15+AC15 -> 481.3501 | S15: =V15+W15+AE15+AF15+AH15+AI15+AK15+AD15 -> 498.39985 | U15: =AR15*bisdepbyhaven!B36/1000 -> 0 | V15: =AS15*bisdepbyhaven!C36/1000 -> 3.5673 | W15: =AT15*bisdepbyhaven!D36/1000 -> 15.80405 | X15: =AU15*bisdepbyhaven!E36/1000 -> 37.3527 | Y15: =AV15*bisdepbyhaven!F36/1000 -> 1.8403 | Z15: =AW15*bisdepbyhaven!G36/1000 -> 94.6337 | AA15: =AX15*bisdepbyhaven!H36/1000 -> 462.85 | AB15: =AY15*bisdepbyhaven!I36/1000 -> 0 | ... AP15: =BM15*bisdepbyhaven!W36/1000 -> 99.7919 | AR15: 0.7 | AS15: 0.05 | AT15: 0.05 | AU15: 0.7 | AV15: 0.7 | AW15: 0.7 | AX15: 1 | AY15: 0 | AZ15: 0.7 | BA15: 1 | BB15: 0.1 | BC15: 0.85 | BD15: 0.7 | BE15: =BE14-0.05 -> 0.85 | BF15: =BF14-0.05 -> 0.85 | BG15: 0.3 | BH15: 1 | BI15: 0.7 | BJ15: 0.7 | BK15: 1 | BL15: 0.7 | BM15: 0.1
A16: 2012 | B16: =T.A1!C19/T.A1!$C19 -> 1 | C16: =T.A1!F19/T.A1!$C19 -> 0.28830679 | D16: =1-C16 -> 0.71169321 | E16: =$D16*Q16/$P16 -> 0.15702695 | F16: =$D16*R16/$P16 -> 0.26696813 | G16: =$D16*S16/$P16 -> 0.28769813 | H16: 2012 | I16: =T.A1!C19 -> 8219.9757 | J16: =T.A1!F19 -> 2369.8748 | K16: =I16-J16 -> 5850.1009 | L16: =E16*$I16 -> 1290.7577 | M16: =F16*$I16 -> 2194.4715 | N16: =G16*$I16 -> 2364.8717 | P16: =Q16+R16+S16 -> 1298.3847 | Q16: =AJ16+AN16+AB16+AP16 -> 286.4737 | R16: =X16+Y16+Z16+AG16+AL16+AM16+AO16+U16+AC16 -> 487.046 | S16: =V16+W16+AE16+AF16+AH16+AI16+AK16+AD16 -> 524.865 | U16: =AR16*bisdepbyhaven!B37/1000 -> 0 | V16: =AS16*bisdepbyhaven!C37/1000 -> 3.3664132 | W16: =AT16*bisdepbyhaven!D37/1000 -> 14.77225 | X16: =AU16*bisdepbyhaven!E37/1000 -> 38.7485 | Y16: =AV16*bisdepbyhaven!F37/1000 -> 1.4707 | Z16: =AW16*bisdepbyhaven!G37/1000 -> 86.499 | AA16: =AX16*bisdepbyhaven!H37/1000 -> 478.287 | AB16: =AY16*bisdepbyhaven!I37/1000 -> 0 | ... AP16: =BM16*bisdepbyhaven!W37/1000 -> 101.3683 | AR16: 0.7 | AS16: 0.05 | AT16: 0.05 | AU16: 0.7 | AV16: 0.7 | AW16: 0.7 | AX16: 1 | AY16: 0 | AZ16: 0.7 | BA16: 1 | BB16: 0.1 | BC16: 0.8 | BD16: 0.7 | BE16: =BE15-0.05 -> 0.8 | BF16: =BF15-0.05 -> 0.8 | BG16: 0.3 | BH16: 1 | BI16: 0.7 | BJ16: 0.7 | BK16: 1 | BL16: 0.7 | BM16: 0.1
A17: 2013 | B17: =T.A1!C20/T.A1!$C20 -> 1 | C17: =T.A1!F20/T.A1!$C20 -> 0.28592928 | D17: =1-C17 -> 0.71407072 | E17: =$D17*Q17/$P17 -> 0.16774675 | F17: =$D17*R17/$P17 -> 0.28725154 | G17: =$D17*S17/$P17 -> 0.25907243 | H17: 2013 | I17: =T.A1!C20 -> 8475.8163 | J17: =T.A1!F20 -> 2423.484 | K17: =I17-J17 -> 6052.3322 | L17: =E17*$I17 -> 1421.7906 | M17: =F17*$I17 -> 2434.6913 | N17: =G17*$I17 -> 2195.8503 | P17: =Q17+R17+S17 -> 1345.7865 | Q17: =AJ17+AN17+AB17+AP17 -> 316.147 | R17: =X17+Y17+Z17+AG17+AL17+AM17+AO17+U17+AC17 -> 541.3739 | S17: =V17+W17+AE17+AF17+AH17+AI17+AK17+AD17 -> 488.26562 | U17: =AR17*bisdepbyhaven!B38/1000 -> 0 | V17: =AS17*bisdepbyhaven!C38/1000 -> 3.5344301 | W17: =AT17*bisdepbyhaven!D38/1000 -> 12.139987 | X17: =AU17*bisdepbyhaven!E38/1000 -> 41.7767 | Y17: =AV17*bisdepbyhaven!F38/1000 -> 1.68 | Z17: =AW17*bisdepbyhaven!G38/1000 -> 85.7178 | AA17: =AX17*bisdepbyhaven!H38/1000 -> 517.49461 | AB17: =AY17*bisdepbyhaven!I38/1000 -> 0 | ... AP17: =BM17*bisdepbyhaven!W38/1000 -> 120.5587 | AR17: 0.7 | AS17: 0.05 | AT17: 0.05 | AU17: 0.7 | AV17: 0.7 | AW17: 0.7 | AX17: 1 | AY17: 0 | AZ17: 0.7 | BA17: 1 | BB17: 0.1 | BC17: 0.75 | BD17: 0.7 | BE17: =BE16-0.05 -> 0.75 | BF17: =BF16-0.05 -> 0.75 | BG17: 0.3 | BH17: 1 | BI17: 0.7 | BJ17: 0.7 | BK17: 1 | BL17: 0.7 | BM17: 0.1
A18: 2014 | B18: =T.A1!C21/T.A1!$C21 -> 1 | C18: =T.A1!F21/T.A1!$C21 -> 0.24590982 | D18: =1-C18 -> 0.75409018 | E18: =$D18*Q18/$P18 -> 0.18225754 | F18: =$D18*R18/$P18 -> 0.32415016 | G18: =$D18*S18/$P18 -> 0.24768247 | H18: 2014 | I18: =T.A1!C21 -> 9523.3891 | J18: =T.A1!F21 -> 2341.8949 | K18: =I18-J18 -> 7181.4942 | L18: =E18*$I18 -> 1735.7095 | M18: =F18*$I18 -> 3087.0081 | N18: =G18*$I18 -> 2358.7766 | P18: =Q18+R18+S18 -> 1309.6533 | Q18: =AJ18+AN18+AB18+AP18 -> 316.5327 | R18: =X18+Y18+Z18+AG18+AL18+AM18+AO18+U18+AC18 -> 562.9623 | S18: =V18+W18+AE18+AF18+AH18+AI18+AK18+AD18 -> 430.15834 | U18: =AR18*bisdepbyhaven!B39/1000 -> 0 | V18: =AS18*bisdepbyhaven!C39/1000 -> 3.1057203 | W18: =AT18*bisdepbyhaven!D39/1000 -> 12.747183 | X18: =AU18*bisdepbyhaven!E39/1000 -> 40.5503 | Y18: =AV18*bisdepbyhaven!F39/1000 -> 1.6028537 | Z18: =AW18*bisdepbyhaven!G39/1000 -> 57.8872 | AA18: =AX18*bisdepbyhaven!H39/1000 -> 484.68843 | AB18: =AY18*bisdepbyhaven!I39/1000 -> 0 | ... AP18: =BM18*bisdepbyhaven!W39/1000 -> 132.4104 | AR18: 0.7 | AS18: 0.05 | AT18: 0.05 | AU18: 0.7 | AV18: 0.7 | AW18: 0.7 | AX18: 1 | AY18: 0 | AZ18: 0.7 | BA18: 1 | BB18: 0.1 | BC18: 0.7 | BD18: 0.7 | BE18: =BE17-0.05 -> 0.7 | BF18: =BF17-0.05 -> 0.7 | BG18: 0.3 | BH18: 1 | BI18: 0.7 | BJ18: 0.7 | BK18: 1 | BL18: 0.7 | BM18: 0.1
A19: 2015 | B19: =T.A1!C22/T.A1!$C22 -> 1 | C19: =T.A1!F22/T.A1!$C22 -> 0.2327847 | D19: =1-C19 -> 0.7672153 | E19: =$D19*Q19/$P19 -> 0.17471822 | F19: =$D19*R19/$P19 -> 0.35056471 | G19: =$D19*S19/$P19 -> 0.24193237 | H19: 2015 | I19: =T.A1!C22 -> 9523.3891 | J19: =T.A1!F22 -> 2216.8993 | K19: =I19-J19 -> 7306.4898 | L19: =E19*$I19 -> 1663.9096 | M19: =F19*$I19 -> 3338.5641 | N19: =G19*$I19 -> 2304.0161 | P19: =Q19+R19+S19 -> 1220.2527 | Q19: =AJ19+AN19+AB19+AP19 -> 277.8886 | R19: =X19+Y19+Z19+AG19+AL19+AM19+AO19+U19+AC19 -> 557.57169 | S19: =V19+W19+AE19+AF19+AH19+AI19+AK19+AD19 -> 384.79241 | U19: =AR19*bisdepbyhaven!B40/1000 -> 0 | V19: =AS19*bisdepbyhaven!C40/1000 -> 2.5159079 | W19: =AT19*bisdepbyhaven!D40/1000 -> 10.102155 | X19: =AU19*bisdepbyhaven!E40/1000 -> 41.0592 | Y19: =AV19*bisdepbyhaven!F40/1000 -> 1.7873135 | Z19: =AW19*bisdepbyhaven!G40/1000 -> 42.813497 | AA19: =AX19*bisdepbyhaven!H40/1000 -> 459.14778 | AB19: =AY19*bisdepbyhaven!I40/1000 -> 0 | ... AP19: =BM19*bisdepbyhaven!W40/1000 -> 124.0718 | AR19: 0.7 | AS19: 0.05 | AT19: 0.05 | AU19: 0.7 | AV19: 0.7 | AW19: 0.7 | AX19: 1 | AY19: 0 | AZ19: 0.7 | BA19: 1 | BB19: 0.1 | BC19: 0.65 | BD19: 0.7 | BE19: =BE18-0.05 -> 0.65 | BF19: =BF18-0.05 -> 0.65 | BG19: 0.3 | BH19: 1 | BI19: 0.7 | BJ19: 0.7 | BK19: 1 | BL19: 0.7 | BM19: 0.1
A20: 2016 | B20: =T.A1!C23/T.A1!$C23 -> 1 | C20: =T.A1!F23/T.A1!$C23 -> 0.26929655 | D20: =1-C20 -> 0.73070345 | E20: =$D20*Q20/$P20 -> 0.16058325 | F20: =$D20*R20/$P20 -> 0.34553954 | G20: =$D20*S20/$P20 -> 0.22458067 | H20: 2016 | I20: =T.A1!C23 -> 7905.564 | J20: =T.A1!F23 -> 2128.9411 | K20: =I20-J20 -> 5776.6229 | L20: =E20*$I20 -> 1269.5011 | M20: =F20*$I20 -> 2731.685 | N20: =G20*$I20 -> 1775.4368 | P20: =Q20+R20+S20 -> 1182.8866 | Q20: =AJ20+AN20+AB20+AP20 -> 259.9574 | R20: =X20+Y20+Z20+AG20+AL20+AM20+AO20+U20+AC20 -> 559.37069 | S20: =V20+W20+AE20+AF20+AH20+AI20+AK20+AD20 -> 363.55852 | U20: =AR20*bisdepbyhaven!B41/1000 -> 0 | V20: =AS20*bisdepbyhaven!C41/1000 -> 3.5439351 | W20: =AT20*bisdepbyhaven!D41/1000 -> 8.3067271 | X20: =AU20*bisdepbyhaven!E41/1000 -> 38.71 | Y20: =AV20*bisdepbyhaven!F41/1000 -> 1.5422512 | Z20: =AW20*bisdepbyhaven!G41/1000 -> 31.416636 | AA20: =AX20*bisdepbyhaven!H41/1000 -> 439.54459 | AB20: =AY20*bisdepbyhaven!I41/1000 -> 0 | ... AP20: =BM20*bisdepbyhaven!W41/1000 -> 138.6039 | AR20: 0.7 | AS20: 0.05 | AT20: 0.05 | AU20: 0.7 | AV20: 0.7 | AW20: 0.7 | AX20: 1 | AY20: 0 | AZ20: 0.7 | BA20: 1 | BB20: 0.1 | BC20: 0.65 | BD20: 0.7 | BE20: 0.65 | BF20: 0.65 | BG20: 0.3 | BH20: 0.9 | BI20: 0.5 | BJ20: 0.5 | BK20: 1 | BL20: 0.7 | BM20: 0.1
A21: 2017 | B21: =T.A1!C24/T.A1!$C24 -> 1 | C21: =T.A1!F24/T.A1!$C24 -> 0.25923151 | D21: =1-C21 -> 0.74076849 | E21: =$D21*Q21/$P21 -> 0.14503237 | F21: =$D21*R21/$P21 -> 0.35648831 | G21: =$D21*S21/$P21 -> 0.23924781 | H21: 2017 | I21: =T.A1!C24 -> 9429.1896 | J21: =T.A1!F24 -> 2444.343 | K21: =I21-J21 -> 6984.8465 | L21: =E21*$I21 -> 1367.5377 | M21: =F21*$I21 -> 3361.3958 | N21: =G21*$I21 -> 2255.913 | P21: =Q21+R21+S21 -> 1230.8761 | Q21: =AJ21+AN21+AB21+AP21 -> 240.98876 | R21: =X21+Y21+Z21+AG21+AL21+AM21+AO21+U21+AC21 -> 592.34827 | S21: =V21+W21+AE21+AF21+AH21+AI21+AK21+AD21 -> 397.53906 | U21: =AR21*bisdepbyhaven!B42/1000 -> 0 | V21: =AS21*bisdepbyhaven!C42/1000 -> 3.6098005 | W21: =AT21*bisdepbyhaven!D42/1000 -> 5.1572729 | X21: =AU21*bisdepbyhaven!E42/1000 -> 38.0058 | Y21: =AV21*bisdepbyhaven!F42/1000 -> 1.1317635 | Z21: =AW21*bisdepbyhaven!G42/1000 -> 24.74946 | AA21: =AX21*bisdepbyhaven!H42/1000 -> 453.83133 | AB21: =AY21*bisdepbyhaven!I42/1000 -> 0 | ... AP21: =BM21*bisdepbyhaven!W42/1000 -> 139.4132 | AR21: 0.7 | AS21: 0.05 | AT21: 0.05 | AU21: 0.7 | AV21: 0.7 | AW21: 0.7 | AX21: 1 | AY21: 0 | AZ21: 0.7 | BA21: 1 | BB21: 0.1 | BC21: 0.65 | BD21: 0.7 | BE21: 0.65 | BF21: 0.65 | BG21: 0.3 | BH21: 0.8 | BI21: 0.5 | BJ21: 0.5 | BK21: 1 | BL21: 0.7 | BM21: 0.1
A22: 2018 | B22: =T.A1!C25/T.A1!$C25 -> 1 | C22: =T.A1!F25/T.A1!$C25 -> 0.26028104 | D22: =1-C22 -> 0.73971896 | E22: =$D22*Q22/$P22 -> 0.13606096 | F22: =$D22*R22/$P22 -> 0.3758178 | G22: =$D22*S22/$P22 -> 0.2278402 | H22: 2018 | I22: =T.A1!C25 -> 8765.7848 | J22: =T.A1!F25 -> 2281.5676 | K22: =I22-J22 -> 6484.2172 | L22: =E22*$I22 -> 1192.6811 | M22: =F22*$I22 -> 3294.3379 | N22: =G22*$I22 -> 1997.1982 | P22: =Q22+R22+S22 -> 1214.7796 | Q22: =AJ22+AN22+AB22+AP22 -> 223.44172 | R22: =X22+Y22+Z22+AG22+AL22+AM22+AO22+U22+AC22 -> 617.17465 | S22: =V22+W22+AE22+AF22+AH22+AI22+AK22+AD22 -> 374.16322 | U22: =AR22*bisdepbyhaven!B43/1000 -> 0 | V22: =AS22*bisdepbyhaven!C43/1000 -> 3.9148084 | W22: =AT22*bisdepbyhaven!D43/1000 -> 4.142212 | X22: =AU22*bisdepbyhaven!E43/1000 -> 38.64 | Y22: =AV22*bisdepbyhaven!F43/1000 -> 0.8083628 | Z22: =AW22*bisdepbyhaven!G43/1000 -> 23.743168 | AA22: =AX22*bisdepbyhaven!H43/1000 -> 453.33616 | AB22: =AY22*bisdepbyhaven!I43/1000 -> 0 | ... AP22: =BM22*bisdepbyhaven!W43/1000 -> 147.7495 | AR22: 0.7 | AS22: 0.05 | AT22: 0.05 | AU22: 0.7 | AV22: 0.7 | AW22: 0.7 | AX22: 1 | AY22: 0 | AZ22: 0.7 | BA22: 1 | BB22: 0.1 | BC22: 0.65 | BD22: 0.7 | BE22: 0.65 | BF22: 0.65 | BG22: 0.3 | BH22: 0.7 | BI22: 0.5 | BJ22: 0.5 | BK22: 1 | BL22: 0.7 | BM22: 0.1
A23: 2019 | B23: =T.A1!C26/T.A1!$C26 -> 1 | C23: =T.A1!F26/T.A1!$C26 -> 0.24156538 | D23: =1-C23 -> 0.75843462 | E23: =$D23*Q23/$P23 -> 0.13881687 | F23: =$D23*R23/$P23 -> 0.39183617 | G23: =$D23*S23/$P23 -> 0.22778159 | H23: 2019 | I23: =T.A1!C26 -> 10740.665 | J23: =T.A1!F26 -> 2594.5729 | K23: =I23-J23 -> 8146.0926 | L23: =E23*$I23 -> 1490.9855 | M23: =F23*$I23 -> 4208.5812 | N23: =G23*$I23 -> 2446.5259 | P23: =Q23+R23+S23 -> 1195.9527 | Q23: =AJ23+AN23+AB23+AP23 -> 218.89613 | R23: =X23+Y23+Z23+AG23+AL23+AM23+AO23+U23+AC23 -> 617.87463 | S23: =V23+W23+AE23+AF23+AH23+AI23+AK23+AD23 -> 359.18192 | U23: =AR23*bisdepbyhaven!B44/1000 -> 0 | V23: =AS23*bisdepbyhaven!C44/1000 -> 4.584365 | W23: =AT23*bisdepbyhaven!D44/1000 -> 3.4038886 | X23: =AU23*bisdepbyhaven!E44/1000 -> 37.9085 | Y23: =AV23*bisdepbyhaven!F44/1000 -> 0.948444 | Z23: =AW23*bisdepbyhaven!G44/1000 -> 27.281703 | AA23: =AX23*bisdepbyhaven!H44/1000 -> 461.05079 | AB23: =AY23*bisdepbyhaven!I44/1000 -> 0 | ... AP23: =BM23*bisdepbyhaven!W44/1000 -> 152.0242 | AR23: 0.7 | AS23: 0.05 | AT23: 0.05 | AU23: 0.7 | AV23: 0.7 | AW23: 0.7 | AX23: 1 | AY23: 0 | AZ23: 0.7 | BA23: 1 | BB23: 0.1 | BC23: 0.65 | BD23: 0.7 | BE23: 0.65 | BF23: 0.65 | BG23: 0.3 | BH23: 0.6 | BI23: 0.5 | BJ23: 0.5 | BK23: 1 | BL23: 0.7 | BM23: 0.1
A24: 2020 | B24: =T.A1!C27/T.A1!$C27 -> 1 | C24: =T.A1!F27/T.A1!$C27 -> 0.21477956 | D24: =1-C24 -> 0.78522044 | E24: =$D24*Q24/$P24 -> 0.14655107 | F24: =$D24*R24/$P24 -> 0.40358536 | G24: =$D24*S24/$P24 -> 0.23508402 | H24: 2020 | I24: =T.A1!C27 -> 12856.722 | J24: =T.A1!F27 -> 2761.3611 | K24: =I24-J24 -> 10095.361 | L24: =E24*$I24 -> 1884.1664 | M24: =F24*$I24 -> 5188.7848 | N24: =G24*$I24 -> 3022.4099 | P24: =Q24+R24+S24 -> 1289.2841 | Q24: =AJ24+AN24+AB24+AP24 -> 240.62793 | R24: =X24+Y24+Z24+AG24+AL24+AM24+AO24+U24+AC24 -> 662.66256 | S24: =V24+W24+AE24+AF24+AH24+AI24+AK24+AD24 -> 385.99363 | U24: =AR24*bisdepbyhaven!B45/1000 -> 0 | V24: =AS24*bisdepbyhaven!C45/1000 -> 5.1919287 | W24: =AT24*bisdepbyhaven!D45/1000 -> 3.5636416 | X24: =AU24*bisdepbyhaven!E45/1000 -> 32.9028 | Y24: =AV24*bisdepbyhaven!F45/1000 -> 0.8630181 | Z24: =AW24*bisdepbyhaven!G45/1000 -> 23.289931 | AA24: =AX24*bisdepbyhaven!H45/1000 -> 528.96184 | AB24: =AY24*bisdepbyhaven!I45/1000 -> 0 | ... AP24: =BM24*bisdepbyhaven!W45/1000 -> 172.115 | AR24: 0.7 | AS24: 0.05 | AT24: 0.05 | AU24: 0.7 | AV24: 0.7 | AW24: 0.7 | AX24: 1 | AY24: 0 | AZ24: 0.7 | BA24: 1 | BB24: 0.1 | BC24: 0.65 | BD24: 0.7 | BE24: 0.65 | BF24: 0.65 | BG24: 0.3 | BH24: 0.5 | BI24: 0.5 | BJ24: 0.5 | BK24: 1 | BL24: 0.7 | BM24: 0.1
A25: 2021 | B25: =T.A1!C28/T.A1!$C28 -> 1 | C25: =T.A1!F28/T.A1!$C28 -> 0.21565889 | D25: =1-C25 -> 0.78434111 | E25: =$D25*Q25/$P25 -> 0.15250814 | F25: =$D25*R25/$P25 -> 0.40575862 | G25: =$D25*S25/$P25 -> 0.22607435 | H25: 2021 | I25: =T.A1!C28 -> 14033.606 | J25: =T.A1!F28 -> 3026.4719 | K25: =I25-J25 -> 11007.134 | L25: =E25*$I25 -> 2140.2392 | M25: =F25*$I25 -> 5694.2566 | N25: =G25*$I25 -> 3172.6384 | P25: =Q25+R25+S25 -> 1334.0237 | Q25: =AJ25+AN25+AB25+AP25 -> 259.38902 | R25: =X25+Y25+Z25+AG25+AL25+AM25+AO25+U25+AC25 -> 690.12269 | S25: =V25+W25+AE25+AF25+AH25+AI25+AK25+AD25 -> 384.51195 | U25: =AR25*bisdepbyhaven!B46/1000 -> 0 | V25: =AS25*bisdepbyhaven!C46/1000 -> 4.5852696 | W25: =AT25*bisdepbyhaven!D46/1000 -> 3.4418327 | X25: =AU25*bisdepbyhaven!E46/1000 -> 35.1995 | Y25: =AV25*bisdepbyhaven!F46/1000 -> 0.808871 | Z25: =AW25*bisdepbyhaven!G46/1000 -> 24.052909 | AA25: =AX25*bisdepbyhaven!H46/1000 -> 555.02971 | AB25: =AY25*bisdepbyhaven!I46/1000 -> 0 | ... AP25: =BM25*bisdepbyhaven!W46/1000 -> 197.4 | AR25: 0.7 | AS25: 0.05 | AT25: 0.05 | AU25: 0.7 | AV25: 0.7 | AW25: 0.7 | AX25: 1 | AY25: 0 | AZ25: 0.7 | BA25: 1 | BB25: 0.1 | BC25: 0.65 | BD25: 0.7 | BE25: 0.65 | BF25: 0.65 | BG25: 0.3 | BH25: 0.4 | BI25: 0.5 | BJ25: 0.5 | BK25: 1 | BL25: 0.7 | BM25: 0.1
A26: 2022 | B26: =T.A1!C29/T.A1!$C29 -> 1 | C26: =T.A1!F29/T.A1!$C29 -> 0.21433309 | D26: =1-C26 -> 0.78566691 | E26: =$D26*Q26/$P26 -> 0.15423036 | F26: =$D26*R26/$P26 -> 0.41178046 | G26: =$D26*S26/$P26 -> 0.21965609 | H26: 2022 | I26: =T.A1!C29 -> 12387.728 | J26: =T.A1!F29 -> 2655.1 | K26: =I26-J26 -> 9732.6282 | L26: =E26*$I26 -> 1910.5637 | M26: =F26*$I26 -> 5101.0245 | N26: =G26*$I26 -> 2721.04 | P26: =Q26+R26+S26 -> 1326.1075 | Q26: =AJ26+AN26+AB26+AP26 -> 260.32155 | R26: =X26+Y26+Z26+AG26+AL26+AM26+AO26+U26+AC26 -> 695.03391 | S26: =V26+W26+AE26+AF26+AH26+AI26+AK26+AD26 -> 370.75201 | U26: =AR26*bisdepbyhaven!B47/1000 -> 0 | V26: =AS26*bisdepbyhaven!C47/1000 -> 5.291047 | W26: =AT26*bisdepbyhaven!D47/1000 -> 3.4298594 | X26: =AU26*bisdepbyhaven!E47/1000 -> 36.827 | Y26: =AV26*bisdepbyhaven!F47/1000 -> 1.1743438 | Z26: =AW26*bisdepbyhaven!G47/1000 -> 14.763034 | AA26: =AX26*bisdepbyhaven!H47/1000 -> 506.78177 | AB26: =AY26*bisdepbyhaven!I47/1000 -> 0 | ... AP26: =BM26*bisdepbyhaven!W47/1000 -> 202.2316 | AR26: 0.7 | AS26: 0.05 | AT26: 0.05 | AU26: 0.7 | AV26: 0.7 | AW26: 0.7 | AX26: 1 | AY26: 0 | AZ26: 0.7 | BA26: 1 | BB26: 0.1 | BC26: 0.65 | BD26: 0.7 | BE26: 0.65 | BF26: 0.65 | BG26: 0.3 | BH26: 0.4 | BI26: 0.5 | BJ26: 0.5 | BK26: 1 | BL26: 0.7 | BM26: 0.1
A27: AJZ 2006-07 | B27: 1 | C27: 0.47423739 | D27: 0.52576261 | E27: 0.1125643 | F27: 0.14571989 | G27: 0.26747843 | H27: 2006-07 | I27: 5623.6645 | J27: 2666.952 | K27: 2956.7125 | L27: 633.02386 | M27: 819.47976 | N27: 1504.2089
A30: Source: build_bis.do outsheets the "bisdepbyhaven" Excel sheet from which the share of each tax haven in non-Swiss offshore wealth is constructed
A32: American havens: Cayman Islands, Panama, part of US (see weights in this sheet col. AP sq., same as in build_offshore21)
A33: Asian havens: Hong Kong, Singapore, Macao, Malaysia, Bahrain, as well as Bahamas, Bermuda, Nethd Antilles. See weights.
A34: European havens: Cyprus, Guernesey, Jersey, Isle of Man, Luxembourg, part of Austria, Belgium & UK (see weights)

Sheet T.A2b
A2: Table A2b: Where is the world's offshore wealth located? (with details)
B3: Share of world's offshore wealth
B4: Total offshore wealth | C4: Switzerland | D4: Tax havens other than Switzerland | E4: Cayman Islands | F4: Panama | G4: US | H4: Hong Kong | I4: Singapore | J4: Macao | K4: Malaysia | L4: Bahrain | M4: Bahamas | N4: Bermuda | O4: Guernsey | P4: Jersey | Q4: Isle of Man | R4: Luxembourg | S4: Cyprus | T4: UK | U4: Netherlands Antilles (then Curaçao) | V4: Austria | W4: Belgium
A5: 2001 | B5: =T.A1!C8/T.A1!$C8 -> 1 | C5: =T.A1!F8/T.A1!$C8 -> 0.38388394 | D5: =1-C5 -> 0.61611606 | E5: =T.A2!E5*T.A2!AJ5/T.A2!Q5 -> 0.081635507 | F5: =T.A2!E5*T.A2!AN5/T.A2!Q5 -> 0 | G5: =T.A2!E5*T.A2!AP5/T.A2!Q5 -> 0.016471383 | H5: =T.A2!$F5*T.A2!AG5/T.A2!$R5 -> 0.046127795 | I5: =T.A2!$F5*T.A2!AO5/T.A2!$R5 -> 0.071133098 | J5: =T.A2!$F5*T.A2!AL5/T.A2!$R5 -> 0 | K5: =T.A2!$F5*T.A2!AM5/T.A2!$R5 -> 0 | L5: =T.A2!$F5*T.A2!X5/T.A2!$R5 -> 0.015241998 | M5: =T.A2!$F5*T.A2!Z5/T.A2!$R5 -> 0.056355779 | N5: =T.A2!$F5*T.A2!Y5/T.A2!$R5 -> 0 | O5: =T.A2!$G5*T.A2!AF5/T.A2!$S5 -> 0.041570556 | P5: =T.A2!$G5*T.A2!AI5/T.A2!$S5 -> 0.063307111 | Q5: =T.A2!$G5*T.A2!AH5/T.A2!$S5 -> 0.019808849 | R5: =T.A2!$G5*T.A2!AK5/T.A2!$S5 -> 0.11403922 | S5: =T.A2!$G5*T.A2!AD5/T.A2!$S5 -> 0.011340557 | T5: =T.A2!$G5*T.A2!AE5/T.A2!$S5 -> 0.04168859 | U5: =T.A2!$F5*T.A2!U5/T.A2!$R5 -> 0.00482286 | V5: =T.A2!$G5*T.A2!V5/T.A2!$S5 -> 0.0025590172 | W5: =T.A2!$G5*T.A2!W5/T.A2!$S5 -> 0.030013747
A6: 2002 | B6: =T.A1!C9/T.A1!$C9 -> 1 | C6: =T.A1!F9/T.A1!$C9 -> 0.38549383 | D6: =1-C6 -> 0.61450617 | E6: =T.A2!E6*T.A2!AJ6/T.A2!Q6 -> 0.11078511 | F6: =T.A2!E6*T.A2!AN6/T.A2!Q6 -> 1.0774915e-05 | G6: =T.A2!E6*T.A2!AP6/T.A2!Q6 -> 0.017429669 | H6: =T.A2!$F6*T.A2!AG6/T.A2!$R6 -> 0.035358383 | I6: =T.A2!$F6*T.A2!AO6/T.A2!$R6 -> 0.068003807 | J6: =T.A2!$F6*T.A2!AL6/T.A2!$R6 -> 0 | K6: =T.A2!$F6*T.A2!AM6/T.A2!$R6 -> 0 | L6: =T.A2!$F6*T.A2!X6/T.A2!$R6 -> 0.011665835 | M6: =T.A2!$F6*T.A2!Z6/T.A2!$R6 -> 0.039839173 | N6: =T.A2!$F6*T.A2!Y6/T.A2!$R6 -> 0.0010304135 | O6: =T.A2!$G6*T.A2!AF6/T.A2!$S6 -> 0.029451988 | P6: =T.A2!$G6*T.A2!AI6/T.A2!$S6 -> 0.06748744 | Q6: =T.A2!$G6*T.A2!AH6/T.A2!$S6 -> 0.020909138 | R6: =T.A2!$G6*T.A2!AK6/T.A2!$S6 -> 0.11055643 | S6: =T.A2!$G6*T.A2!AD6/T.A2!$S6 -> 0.011375551 | T6: =T.A2!$G6*T.A2!AE6/T.A2!$S6 -> 0.046207645 | U6: =T.A2!$F6*T.A2!U6/T.A2!$R6 -> 0.0050545957 | V6: =T.A2!$G6*T.A2!V6/T.A2!$S6 -> 0.0033752008 | W6: =T.A2!$G6*T.A2!W6/T.A2!$S6 -> 0.03596501
A7: 2003 | B7: =T.A1!C10/T.A1!$C10 -> 1 | C7: =T.A1!F10/T.A1!$C10 -> 0.43598379 | D7: =1-C7 -> 0.56401621 | E7: =T.A2!E7*T.A2!AJ7/T.A2!Q7 -> 0.085406801 | F7: =T.A2!E7*T.A2!AN7/T.A2!Q7 -> 0.003094604 | G7: =T.A2!E7*T.A2!AP7/T.A2!Q7 -> 0.026556676 | H7: =T.A2!$F7*T.A2!AG7/T.A2!$R7 -> 0.031475191 | I7: =T.A2!$F7*T.A2!AO7/T.A2!$R7 -> 0.054769232 | J7: =T.A2!$F7*T.A2!AL7/T.A2!$R7 -> 0.00088909544 | K7: =T.A2!$F7*T.A2!AM7/T.A2!$R7 -> 0 | L7: =T.A2!$F7*T.A2!X7/T.A2!$R7 -> 0.0091421357 | M7: =T.A2!$F7*T.A2!Z7/T.A2!$R7 -> 0.037208622 | N7: =T.A2!$F7*T.A2!Y7/T.A2!$R7 -> 0.00089515844 | O7: =T.A2!$G7*T.A2!AF7/T.A2!$S7 -> 0.027027982 | P7: =T.A2!$G7*T.A2!AI7/T.A2!$S7 -> 0.070925947 | Q7: =T.A2!$G7*T.A2!AH7/T.A2!$S7 -> 0.017891414 | R7: =T.A2!$G7*T.A2!AK7/T.A2!$S7 -> 0.10037789 | S7: =T.A2!$G7*T.A2!AD7/T.A2!$S7 -> 0.010851605 | T7: =T.A2!$G7*T.A2!AE7/T.A2!$S7 -> 0.046796079 | U7: =T.A2!$F7*T.A2!U7/T.A2!$R7 -> 0.0042345714 | V7: =T.A2!$G7*T.A2!V7/T.A2!$S7 -> 0.0033250598 | W7: =T.A2!$G7*T.A2!W7/T.A2!$S7 -> 0.033148146
